Workbook

Sheet How to Fill
A1: How to Write an Attribute List
A2: An Attribute List (AL) lists every behavior of the module that verification must prove. It is written from the spec, BEFORE the Verification Plan and the environment: the VP (stimulus scenarios, checkers, coverage) is built from the AL.
A4: Column | B4: Meaning
A5: ID | B5: Unique attribute ID (group prefix + number). Referenced from the VP and from test logs.
A6: Group | B6: Logical grouping of attributes (by feature, lane, attribute type, …).
A7: Attribute (The module shall … when …) | B7: What the module does, written as an observable behavior triggered by a stimulus: "The module shall … when …".
A8: Notes / Assumptions | B8: Constraints, parameters, and assumptions the attribute depends on.
A9: Test Case (standard & corner cases) | B9: The concrete scenarios that must be exercised — standard cases and corner cases. One row per case.
A10: Priority | B10: High / Medium / Low — trade-off between importance and development time.
A11: Implemented (V / X) | B11: V = the scenario is implemented in the verification environment (stimulus + checker). X = not yet.
A12: Checked (V / X) | B12: V = the scenario was actually hit and measured by functional coverage. X = not yet. (Both status columns stay X when the AL is first written — they are filled in later, during verification.)
A14: Writing good attributes
A15: • System assumptions: conditions the module cannot work without (e.g. valid interfaces, legal parameter ranges). They are not stimulated, but the environment must respect them.
A16: • Attributes describe what the module DOES in response to a stimulus — phrase them as "The module shall … when …".
A17: • Group attributes by common sense: by lane, by feature, by attribute type, etc. Give each group an ID prefix (e.g. LCK, SIZ, PAR).
A18: • Split every attribute into concrete test cases, one per row: the standard case plus every corner case (min, min+1, max-1, max, out-of-range, error injection).
A19: • Priority reflects the trade-off between importance and development time: High = must have for sign-off, Medium = should have, Low = nice to have.
A20: • Implemented (V/X): the scenario is generated and checked in the environment. Checked (V/X): functional coverage shows the scenario was actually hit.
A21: • Keep the AL independent of the verification environment: describe behavior and scenarios in spec terms only (no coverpoints, sequences or test knobs) — those belong in the VP.
A22: • Write each test case so it can later become one VP item: a clear stimulus and the expected module response.

Sheet Summary
A1: Verification Progress Summary — CTRL Stage
A2: All numbers are live formulas over the 'AL' sheet — they update when you change V / X.
A4: Group | B4: Test Cases | C4: Implemented | D4: % Impl. | E4: Checked | F4: % Checked
A5: System assumptions | B5: =COUNTIFS(AL!$I$6:$I$68,"SYS",AL!$E$6:$E$68,"<>") | C5: =COUNTIFS(AL!$I$6:$I$68,"SYS",AL!$G$6:$G$68,"V") | D5: =IF(B5=0,0,C5/B5) | E5: =COUNTIFS(AL!$I$6:$I$68,"SYS",AL!$H$6:$H$68,"V") | F5: =IF(B5=0,0,E5/B5)
A6: LR op: SET | B6: =COUNTIFS(AL!$I$6:$I$68,"SET",AL!$E$6:$E$68,"<>") | C6: =COUNTIFS(AL!$I$6:$I$68,"SET",AL!$G$6:$G$68,"V") | D6: =IF(B6=0,0,C6/B6) | E6: =COUNTIFS(AL!$I$6:$I$68,"SET",AL!$H$6:$H$68,"V") | F6: =IF(B6=0,0,E6/B6)
A7: LR ops: ADD / SUB | B7: =COUNTIFS(AL!$I$6:$I$68,"ADS",AL!$E$6:$E$68,"<>") | C7: =COUNTIFS(AL!$I$6:$I$68,"ADS",AL!$G$6:$G$68,"V") | D7: =IF(B7=0,0,C7/B7) | E7: =COUNTIFS(AL!$I$6:$I$68,"ADS",AL!$H$6:$H$68,"V") | F7: =IF(B7=0,0,E7/B7)
A8: LR op: INC.MODP2 | B8: =COUNTIFS(AL!$I$6:$I$68,"MOD",AL!$E$6:$E$68,"<>") | C8: =COUNTIFS(AL!$I$6:$I$68,"MOD",AL!$G$6:$G$68,"V") | D8: =IF(B8=0,0,C8/B8) | E8: =COUNTIFS(AL!$I$6:$I$68,"MOD",AL!$H$6:$H$68,"V") | F8: =IF(B8=0,0,E8/B8)
A9: LR ops: INC / DEC | B9: =COUNTIFS(AL!$I$6:$I$68,"IDC",AL!$E$6:$E$68,"<>") | C9: =COUNTIFS(AL!$I$6:$I$68,"IDC",AL!$G$6:$G$68,"V") | D9: =IF(B9=0,0,C9/B9) | E9: =COUNTIFS(AL!$I$6:$I$68,"IDC",AL!$H$6:$H$68,"V") | F9: =IF(B9=0,0,E9/B9)
A10: LR ops: ADDB / ADDBI | B10: =COUNTIFS(AL!$I$6:$I$68,"ADB",AL!$E$6:$E$68,"<>") | C10: =COUNTIFS(AL!$I$6:$I$68,"ADB",AL!$G$6:$G$68,"V") | D10: =IF(B10=0,0,C10/B10) | E10: =COUNTIFS(AL!$I$6:$I$68,"ADB",AL!$H$6:$H$68,"V") | F10: =IF(B10=0,0,E10/B10)
A11: LR lanes (x3) | B11: =COUNTIFS(AL!$I$6:$I$68,"LAN",AL!$E$6:$E$68,"<>") | C11: =COUNTIFS(AL!$I$6:$I$68,"LAN",AL!$G$6:$G$68,"V") | D11: =IF(B11=0,0,C11/B11) | E11: =COUNTIFS(AL!$I$6:$I$68,"LAN",AL!$H$6:$H$68,"V") | F11: =IF(B11=0,0,E11/B11)
A12: LR hazards & timing | B12: =COUNTIFS(AL!$I$6:$I$68,"TIM",AL!$E$6:$E$68,"<>") | C12: =COUNTIFS(AL!$I$6:$I$68,"TIM",AL!$G$6:$G$68,"V") | D12: =IF(B12=0,0,C12/B12) | E12: =COUNTIFS(AL!$I$6:$I$68,"TIM",AL!$H$6:$H$68,"V") | F12: =IF(B12=0,0,E12/B12)
A13: LR / CR state & reset | B13: =COUNTIFS(AL!$I$6:$I$68,"LRF",AL!$E$6:$E$68,"<>") | C13: =COUNTIFS(AL!$I$6:$I$68,"LRF",AL!$G$6:$G$68,"V") | D13: =IF(B13=0,0,C13/B13) | E13: =COUNTIFS(AL!$I$6:$I$68,"LRF",AL!$H$6:$H$68,"V") | F13: =IF(B13=0,0,E13/B13)
A14: COND: branches | B14: =COUNTIFS(AL!$I$6:$I$68,"CND",AL!$E$6:$E$68,"<>") | C14: =COUNTIFS(AL!$I$6:$I$68,"CND",AL!$G$6:$G$68,"V") | D14: =IF(B14=0,0,C14/B14) | E14: =COUNTIFS(AL!$I$6:$I$68,"CND",AL!$H$6:$H$68,"V") | F14: =IF(B14=0,0,E14/B14)
A15: COND: HALT | B15: =COUNTIFS(AL!$I$6:$I$68,"HLT",AL!$E$6:$E$68,"<>") | C15: =COUNTIFS(AL!$I$6:$I$68,"HLT",AL!$G$6:$G$68,"V") | D15: =IF(B15=0,0,C15/B15) | E15: =COUNTIFS(AL!$I$6:$I$68,"HLT",AL!$H$6:$H$68,"V") | F15: =IF(B15=0,0,E15/B15)
A16: Fetch / PC | B16: =COUNTIFS(AL!$I$6:$I$68,"FET",AL!$E$6:$E$68,"<>") | C16: =COUNTIFS(AL!$I$6:$I$68,"FET",AL!$G$6:$G$68,"V") | D16: =IF(B16=0,0,C16/B16) | E16: =COUNTIFS(AL!$I$6:$I$68,"FET",AL!$H$6:$H$68,"V") | F16: =IF(B16=0,0,E16/B16)
A17: Dispatch & XMEM load | B17: =COUNTIFS(AL!$I$6:$I$68,"DSP",AL!$E$6:$E$68,"<>") | C17: =COUNTIFS(AL!$I$6:$I$68,"DSP",AL!$G$6:$G$68,"V") | D17: =IF(B17=0,0,C17/B17) | E17: =COUNTIFS(AL!$I$6:$I$68,"DSP",AL!$H$6:$H$68,"V") | F17: =IF(B17=0,0,E17/B17)
A18: Memory wait (spec TBD) | B18: =COUNTIFS(AL!$I$6:$I$68,"MEM",AL!$E$6:$E$68,"<>") | C18: =COUNTIFS(AL!$I$6:$I$68,"MEM",AL!$G$6:$G$68,"V") | D18: =IF(B18=0,0,C18/B18) | E18: =COUNTIFS(AL!$I$6:$I$68,"MEM",AL!$H$6:$H$68,"V") | F18: =IF(B18=0,0,E18/B18)
A19: TOTAL | B19: =SUM(B5:B18) | C19: =SUM(C5:C18) | D19: =IF(B19=0,0,C19/B19) | E19: =SUM(E5:E18) | F19: =IF(B19=0,0,E19/B19)
A21: By priority
A22: Priority | B22: Test Cases | C22: Implemented | D22: % Impl. | E22: Checked | F22: % Checked
A23: High | B23: =COUNTIFS(AL!$F$6:$F$68,"High") | C23: =COUNTIFS(AL!$F$6:$F$68,"High",AL!$G$6:$G$68,"V") | D23: =IF(B23=0,0,C23/B23) | E23: =COUNTIFS(AL!$F$6:$F$68,"High",AL!$H$6:$H$68,"V") | F23: =IF(B23=0,0,E23/B23)
A24: Medium | B24: =COUNTIFS(AL!$F$6:$F$68,"Medium") | C24: =COUNTIFS(AL!$F$6:$F$68,"Medium",AL!$G$6:$G$68,"V") | D24: =IF(B24=0,0,C24/B24) | E24: =COUNTIFS(AL!$F$6:$F$68,"Medium",AL!$H$6:$H$68,"V") | F24: =IF(B24=0,0,E24/B24)
A25: Low | B25: =COUNTIFS(AL!$F$6:$F$68,"Low") | C25: =COUNTIFS(AL!$F$6:$F$68,"Low",AL!$G$6:$G$68,"V") | D25: =IF(B25=0,0,C25/B25) | E25: =COUNTIFS(AL!$F$6:$F$68,"Low",AL!$H$6:$H$68,"V") | F25: =IF(B25=0,0,E25/B25)

Sheet AL
A1: Control (CTRL) Stage — Attribute List (AL): Commands
A2: Written from stage-control spec (ipu-emulator, specs/stage-control) — scope of this revision: the COMMANDS (LR slot x3 lanes, COND slot, fetch/PC, load address, dispatch pass-through). APB/IMEM-CR config and memory-wait are out of scope / placeholder. Cases are scenario classes hit by weighted constrained-random stimulus, not fixed values. Open spec issues: 'Spec Questions' sheet.
E3: PRIORITY | F3: High | G3: Medium | H3: Low
E4: STATUS (Implemented / Checked) | G4: V • Done | H4: X • Not done
A5: ID | B5: Group | C5: Attribute (The module shall … when …) | D5: Notes / Assumptions | E5: Test Case (standard & corner cases) | F5: Priority | G5: Implemented (V / X) | H5: Checked (V / X)
A6: SYSTEM — Assumptions (the module cannot work correctly without these)
A7: SYS-01 | B7: System assumptions | C7: The clock runs, rst is a legal synchronous reset, and the active IMEM bank holds a legal decoded program. | D7: IMEM/CR are loaded over APB — APB and bank swap are outside this AL revision (commands only). | E7: Assumption — not stimulated | F7: High | G7: X | H7: X | I7: SYS
A8: SYS-02 | B8: System assumptions | C8: Programs are legal: no two lanes write the same LR (ADDB/ADDBI write both LR(n) and LR(n+1)); INC.MODP2 k in 1..9; LRD index even; branch / BR targets inside the active bank. | D8: Spec §10.1. What the hardware does on illegal programs is not specified — Spec Questions Q5, Q9, Q12. | E8: Assumption — environment constraints, not stimulated | F8: High | G8: X | H8: X | I8: SYS
A9: SYS-03 | B9: System assumptions | C9: CR0 = 0 and CR1 = 1 are hard-wired, and CR content is static during a kernel. | D9: Host changes CR only through the inactive bank, between kernels. | E9: Assumption — not stimulated | F9: High | G9: X | H9: X | I9: SYS
A10: SYS-04 | B10: System assumptions | C10: Downstream stages and XMEM never back-pressure CTRL. | D10: Memory-wait behavior is not updated in the spec — see group MEM. | E10: Assumption — remove when the memory-wait spec is released | F10: High | G10: X | H10: X | I10: SYS
A11: A. LR SLOT — per opcode (highest-risk area: every op writes state that all later code depends on)
A12: SET-01 | B12: LR op: SET | C12: The module shall write dest with CR[src5[3:0]] when src5[4] = 0, or with the sign-extended 4-bit immediate when src5[4] = 1. | D12: CR0 = 0, CR1 = 1. Immediate range -8..+7. | E12: CR mode: random CR index, CR content and dest [standard] | F12: High | G12: X | H12: X | I12: SET
E13: Immediate mode: random payload and dest [standard] | F13: High | G13: X | H13: X | I13: SET
E14: Boundary class: CR0 / CR1 / CR15, imm min / max / -1, mode-bit boundary [corner] | F14: Medium | G14: X | H14: X | I14: SET
A15: ADS-01 | B15: LR ops: ADD / SUB | C15: The module shall write (src_a + src_b)[31:0] into dest when ADD is issued (src_b = LR or CR). | D15: 32-bit wrap, no saturation, no flags. | E15: Random sources (LR / CR mix) and dest [standard] | F15: High | G15: X | H15: X | I15: ADS
E16: Operands biased to wrap points (0, ±1, 0x7FFFFFFF, 0x80000000, 0xFFFFFFFF) [corner] | F16: High | G16: X | H16: X | I16: ADS
E17: Operand aliasing: dest == src_a / src_b, src_a == src_b [corner] | F17: Medium | G17: X | H17: X | I17: ADS
A18: ADS-02 | B18: LR ops: ADD / SUB | C18: The module shall write (src_a - src_b)[31:0] into dest when SUB is issued. | D18: Operand order matters. | E18: Random sources (LR / CR mix) and dest [standard] | F18: High | G18: X | H18: X | I18: ADS
E19: Operands biased to underflow / wrap points [corner] | F19: High | G19: X | H19: X | I19: ADS
E20: Operand aliasing (loop-counter form SUB LRx LRx CR1) [corner] | F20: Medium | G20: X | H20: X | I20: ADS
A21: MOD-01 | B21: LR op: INC.MODP2 | C21: The module shall write (dst + step) & ((1<<k)-1) into dst when INC.MODP2 is issued. | D21: k 1..9 (encoded k-1). step is a signed 32-bit LR or CR value. | E21: Random k, dst, step (all inside the mask) [standard] | F21: High | G21: X | H21: X | I21: MOD
E22: Wrap class: sum at / around 2^k, negative and large steps, dst already above the mask [corner] | F22: High | G22: X | H22: X | I22: MOD
E23: Step source CR0 / CR1 / LR / dst itself [corner] | F23: Medium | G23: X | H23: X | I23: MOD
E24: Pointer walk: repeated INC.MODP2 over many words (circular buffer) [standard] | F24: Medium | G24: X | H24: X | I24: MOD
A25: IDC-01 | B25: LR ops: INC / DEC | C25: The module shall write dest ± imm (unsigned 8-bit immediate, 32-bit wrap) when INC / DEC is issued. | D25: Same immediate field as ADDBI, but decoded UNSIGNED here. | E25: Random imm and dest [standard] | F25: High | G25: X | H25: X | I25: IDC
E26: imm biased to 0 / 127 / 128 / 255 (unsigned decode) and dest near 0 / 0xFFFFFFFF wrap [corner] | F26: High | G26: X | H26: X | I26: IDC
E27: Long repeated INC / DEC on the same LR (counter) [standard] | F27: Medium | G27: X | H27: X | I27: IDC
A28: ADB-01 | B28: LR ops: ADDB / ADDBI | C28: The module shall add the signed byte (src_b[7:0] for ADDB, imm for ADDBI) to each of the 8 bytes of LRDn, saturating each byte to [0,255]. | D28: LRDn = LR(n+1):LR(n). Byte order inside the pair — Spec Questions Q10. | E28: Random pair content and random signed byte [standard] | F28: High | G28: X | H28: X | I28: ADB
E29: Saturation class: bytes and value biased to 0 / 255 / ±127 / -128, mixed saturating and non-saturating bytes in one op [corner] | F29: High | G29: X | H29: X | I29: ADB
E30: Operand decode class: ADDB src_b with non-zero upper bits; ADDBI imm in both 0..255 and signed spelling [corner] | F30: High | G30: X | H30: X | I30: ADB
E31: Pair addressing: every LRD0..LRD14, only LR(n) and LR(n+1) change; src_b inside the dest pair [standard] | F31: Medium | G31: X | H31: X | I31: ADB
A32: B. LR SLOT — three lanes, hazards, register state
A33: LAN-01 | B33: LR lanes (x3) | C33: The module shall execute any LR opcode in any lane, with up to three LR sub-instructions in parallel in one word. | D33: Lanes are identical. ADDB/ADDBI write two LRs each (Spec Questions Q4); unused lane encoding — Q7. | E33: Random opcode / lane mix, 1..3 active lanes, distinct dests [standard] | F33: High | G33: X | H33: X | I33: LAN
E34: All lanes NOP, and partially NOP words [corner] | F34: Medium | G34: X | H34: X | I34: LAN
E35: Several ADDB / ADDBI pairs in one word [corner] | F35: Medium | G35: X | H35: X | I35: LAN
A36: LAN-02 | B36: LR lanes (x3) | C36: The module shall read all lane source operands from the prior-cycle snapshot, not from another lane's result in the same word. | D36: Spec §5. | E36: Words where one lane reads an LR another lane writes (any lane pair, any opcode), incl. register swap / rotate in one word [corner] | F36: High | G36: X | H36: X | I36: LAN
A37: LAN-03 | B37: LR lanes (x3) | C37: The module shall change only the destination registers named in the word. | D37: Full 16-LR compare every cycle. | E37: All 16 LRs checked each cycle over random programs [standard] | F37: High | G37: X | H37: X | I37: LAN
A38: TIM-01 | B38: LR hazards & timing | C38: The module shall make an LR written in word N visible to LR-ALU sources in words N+1 and later. | E38: Random dependent chains: producer op, consumer op, lane and distance 1..N randomized [standard] | F38: High | G38: X | H38: X | I38: TIM
A39: TIM-02 | B39: LR hazards & timing | C39: The module shall evaluate branch operands (reg1, reg2, BR reg) from the prior-cycle snapshot. | D39: Spec §5 / §10. | E39: LR written in the same word as the branch (old value used) or the word before (new value used), biased so the write flips the outcome [corner] | F39: High | G39: X | H39: X | I39: TIM
A40: TIM-03 | B40: LR hazards & timing | C40: The module shall execute the slots of the branch word itself in both outcomes, and shall give the non-selected fetch candidate no side effect (LR write, load, bus). | D40: PC+1 and label are fetched in parallel; only one may execute. | E40: Taken and not-taken branches whose both candidate words carry LR writes / loads / bus slots [corner] | F40: High | G40: X | H40: X | I40: TIM
...

Sheet Spec Questions
A1: Spec Questions — to close with the designer before the VP is built
A2: Findings from reading specs/stage-control: inconsistencies and gaps that block exact checker expectations.
A4: # | B4: Spec location | C4: Finding | D4: Impact on verification | E4: Question for the designer
A5: Q1 | B5: §10 intro, §8, Summary table | C5: Intro says '11 mnemonics: four LR ops + seven branches'; §8 lists LR ops 'SET/ADD/SUB/INC.MODP2'. The table and §4 list 8 LR ops and 5 branches + HALT (6 COND). | D5: Stale text – risk that the AL misses or invents an opcode. | E5: Confirm the final opcode set is 8 LR + 5 branch + HALT.
A6: Q2 | B6: §2 diagram vs §4 | C6: Diagram says 'CR file 2 x 16 x 20bit' and 'LR file 16 x 20bit'; §4 REG_WIDTH = 32. | D6: Width decides all overflow / wrap corners (0xFFFFFFFF vs 20-bit). | E6: Is every CR/LR 32 bit? (AL assumes 32.)
A7: Q3 | B7: §6.3 vs §10.2 | C7: §6.3 / pseudo-code use next_pc = label (absolute). §10.2 says 'label is a relative offset resolved by the assembler'. | D7: Absolute vs relative changes target computation, wrap and range corners (FET-01). | E7: Does the label field in IMEM hold an absolute address or a PC-relative offset?
A8: Q4 | B8: §1, §10.1.7 | C8: 'Up to three local-register writes per cycle', but ADDB/ADDBI write two LRs (the pair) each → up to six. | D8: Number of LR write ports / pair conflicts (LAN-01, SYS-02). | E8: Is the LR file 6-write? What happens if pairs overlap other lanes?
A9: Q5 | B9: §10.1 (self-reference '§10') | C9: 'Programs must not target the same destination LR from two lanes' – no hardware behavior stated. | D9: Needed to turn SYS-02 into a checker (lane priority? last lane wins? undefined?). | E9: Define the behavior or declare it undefined/ignored.
A10: Q6 | B10: §3.1 | C10: Reset 'clears any pending LR writes' – LR values after reset are not stated. | D10: LRF-02 cannot check the post-reset LR value. | E10: Are LR0..LR15 reset to 0? What is a 'pending LR write'?
A11: Q7 | B11: §5, §10.1 | C11: No LR-slot NOP is mentioned (only COND/load NOP). | D11: LAN-01 assumes an LR NOP encoding. | E11: How is an unused LR lane encoded?
A12: Q8 | B12: §7.1, §9 | C12: xmem_read_en is gated by '!bubble' and refers to '§9.2'; §9 says no hazard interlocks exist and §9.2 does not exist. | D12: Memory-wait / stall behavior is undefined (group MEM is a placeholder). | E12: Provide the updated wait/stall mechanism (stall input? bubble counter? who holds PC / LR commit?).
A13: Q9 | B13: §10.1.4 | C13: INC.MODP2 k is 4 bits encoded k-1, semantic range 1..9; encodings 9..15 are not described. | D13: Expected result for illegal k (SYS-02). | E13: Is the encoding legal-checked, saturated or just masked?
A14: Q10 | B14: §10.1.7-8 | C14: Byte-element order inside LRDn is not stated (which LR holds elements 0-3; element 0 = bits [7:0]?). | D14: ADB-01 checker needs the exact lane mapping. | E14: Confirm element i = LRD bits [8i+7:8i], LR(n) = low half.
A15: Q11 | B15: §1, §7.1 | C15: The load slot 'has no opcode' yet 'writes into R0/R1/R_CYCLIC/R_MASK' – the destination register is not visible on the CTRL ports (only addr + en). | D15: Whether CTRL must forward a destination-select with the load. | E15: Is the destination select part of xmem_read_* or of mult_vliw_bus?
... A19: Q15 | B19: §10.2 | C19: COND pseudo-code reads reg1 and reg2 for every op including BR / HALT; BR reg is also read from the snapshot. | D19: TIM-02 for BR. | E19: Confirm BR target reads the same prior-cycle snapshot as the compares.
